Workbook

Sheet Developer Projects
A1: S.No | B1: Developer | C1: Project Name | D1: Location (Sector / Area) | E1: Project Type | F1: Status | G1: RERA No. | H1: Area (Acres) | I1: Towers | J1: Units | K1: Configuration | L1: Unit Size Range | M1: Price Range (approx.) | N1: Possession / Completion | O1: Key Amenities / Features | P1: Notes
A2: 1 | B2: Nirala India | C2: Nirala Greenshire Phase I | D2: Sector 18, Greater Noida | E2: Residential | F2: Completed
A3: 2 | B3: Nirala India | C3: Nirala Aspire Phase I | D3: Sector 16, Greater Noida West | E3: Residential | F3: Completed | J3: 176 | O3: Completed phase; new phases since launched
A4: 3 | B4: Nirala India | C4: Nirala Aspire Phase II | D4: Sector 16, Greater Noida West | E4: Residential | F4: Ongoing | J4: 950
A5: 4 | B5: Nirala India | C5: Nirala Grand | D5: Sector 1, Greater Noida West | E5: Residential | F5: Ongoing | H5: 10.5 | K5: 2/3/4 BHK | O5: Vastu-compliant; Central Brahmasthal with Banyan Tree; Grand Clubhouse, gym, indoor games; 35+ amenities | P5: Launched ~Dec 2025
A6: 5 | B6: Nirala India | C6: Nirala Estate (Phases 2-5) | D6: Techzone-IV, Greater Noida West | E6: Residential | F6: Ongoing | H6: 25 | I6: 21 | J6: 3600 | K6: 2/3 BHK | M6: From ~₹13,000/sq ft (2BHK ~₹1.29-1.31 Cr, 3BHK ~₹2.49 Cr) | N6: Ph.1 delivered 2017; Ph.2 May 2025; Ph.3&4 Dec 2026; Ph.5 Nov 2027 | O6: 45,000 sq ft clubhouse; 18% open green space; lift ratio ~1:48-1:72
A7: 6 | B7: Nirala India | C7: Nirala Gateway | D7: Sector 12, Greater Noida West | E7: Residential | F7: Ongoing
A8: 7 | B8: Nirala India | C8: Nirala Greenshire Phase II | D8: Sector 2, Noida Extension | E8: Residential | F8: Upcoming | K8: 2/3/4 BHK | O8: Connected to Greater Noida West Link Road
A9: 8 | B9: Nirala World | C9: Nirala Trio | D9: Sector 2, Greater Noida West | E9: Residential | F9: Ongoing | K9: 3 BHK (ultra-luxury) | N9: ~Oct 2026 (approx.) | O9: Central Green/park; 2.5 km from GNW Link Road | P9: Developed under Nirala World brand
A10: 9 | B10: Nirala World | C10: Nirala World (flagship residential) | D10: Greater Noida West | E10: Residential | F10: Ongoing | K10: 2/3/4 BHK
A11: 10 | B11: Nirala World | C11: Nirala World Commercial, Sector 12 | D11: Sector 12, Noida Extension | E11: Commercial | F11: Upcoming | K11: Retail, office space | O11: On Noida-Greater Noida Expressway
A12: 11 | B12: Unibera | C12: Unibera Towers | D12: Sector 1, Greater Noida | E12: Residential (+ commercial block) | F12: Completed | G12: UPRERAPRJ2537 | H12: 4.44 | I12: 5-7 | J12: 711 | K12: 2/3/4 BHK + Other | L12: 635-1475 sq ft | M12: ₹27.90L-48.00L (also cited up to ₹92.41L) | N12: Possession offered Nov 2019 (launched Aug 2016) | O12: Gym, power backup, badminton/basketball court, swimming pool, skating rink; 75% open space | P12: 21 floors; loans via ICICI Bank & PNB
A13: 12 | B13: Bhutani Group | C13: Bhutani Alphathum | D13: Sector 90, Noida | E13: Commercial | F13: Completed | I13: 3 | K13: IT offices, retail, food court | O13: LEED Gold rated; ~53,000 sq ft floor plates; inspired by Singapore architecture
A14: 13 | B14: Bhutani Group | C14: Bhutani Cyberthum | D14: Sector 140A, Noida | E14: Commercial | F14: Completed | K14: Office, retail, food court, co-working
A15: 14 | B15: Bhutani Group | C15: Bhutani Grandthum | D15: Noida Extension / Greater Noida West | E15: Commercial | F15: Completed | K15: Retail, office, co-working, food court | O15: Anchor brands: Allen Solly, Pantaloons, Miraj Cinemas, Reebok, Tata Westside, Van Heusen | P15: Co-branded with Group 108
A16: 15 | B16: Bhutani Group | C16: Bhutani Avenue 62 | D16: Sector 62, Noida | E16: Commercial | F16: Completed | K16: Retail | O16: 5 Lacs+ footfall potential; only retail destination in Sector 62 | P16: Interior waterfall (25m)
A17: 16 | B17: Bhutani Group | C17: Bhutani Experience | D17: Sector 32, Noida | E17: Residential (studio) | F17: Completed | J17: 286 | K17: Studio (0 BHK) | L17: 726-1141 sq ft | O17: Fully furnished, pre-leased 5-star studios | P17: 20 floors
A18: 17 | B18: Bhutani Group | C18: Bhutani City Center 150 | D18: Sector 150, Noida | E18: Commercial | F18: Ongoing | K18: High-street retail, entertainment
A19: 18 | B19: Group 108 | C19: iThum | D19: Sector 62, Noida | E19: Commercial | F19: Completed | O19: Flagship commercial project cited alongside Parmesh Complex, Delhi
A20: 19 | B20: Group 108 | C20: Grandthum | D20: Greater Noida West | E20: Mixed (Residential + Commercial) | F20: Ongoing | K20: Residential + commercial | O20: Co-developed under Bhutani/Group 108 branding
A21: 20 | B21: Group 108 | C21: One FNG | D21: Sector 142, Noida | E21: Commercial | F21: Upcoming | G21: UPRERAPRJ279516 | H21: 14.46 | K21: Office, retail | M21: From ₹60,00,000 | N21: ~2028 | O21: Adjoins Advant Tower & Noida Metro Sector 142 station | P21: Leasehold
A22: 21 | B22: Gulsan Group | C22: Gulshan Dynasty | D22: Greater Noida West / Noida | E22: Residential | F22: Ongoing | N22: Possession available soon | O22: Flagship luxury development | P22: Nearing completion
A23: 22 | B23: Gulsan Group | C23: Gulshan Avante | D23: Greater Noida West | E23: Residential | F23: Ongoing | K23: 4-bedroom luxury concept
A24: 23 | B24: Gulsan Group | C24: Gulshan Bellina | D24: Sector 16, Greater Noida | E24: Residential | F24: Completed | K24: 2/3 BHK | N24: Ready to move | O24: Central lawn, open-air theatre, yoga/meditation decks, gym, pool | P24: 36-year legacy brand
A25: 24 | B25: Gulsan Group | C25: Gulshan Botnia | D25: Sector 144, Noida | E25: Residential | F25: Completed | K25: 2/3 BHK
A26: 25 | B26: Gulsan Group | C26: Gulshan Botnia Phase 2 | D26: Sector 144, Noida | E26: Residential | F26: Upcoming | K26: 2/3 BHK | O26: Clubhouse, jogging track, indoor games, rainwater harvesting, solar lighting
A27: 26 | B27: Gulsan Group | C27: Gulshan Vivante | D27: Sector 137, Noida | E27: Residential | F27: Completed | K27: 2/3 BHK | O27: Clubhouse, pool, landscaped gardens
A28: 27 | B28: Gulsan Group | C28: Gulshan Ikebana | D28: Sector 143, Noida | E28: Residential | F28: Completed
A29: 28 | B29: Gulsan Group | C29: Gulshan One29 | D29: Sector 129, Noida Expressway | E29: Commercial | F29: Completed | O29: One of Gulshan's prime commercial projects
A30: 29 | B30: ATS | C30: ATS One Hamlet | D30: Sector 50, Noida | E30: Residential | F30: Completed | H30: 14.5 | J30: 352 | K30: 3/4 BHK | L30: 1636-3115 sq ft | P30: IRR of 54% recorded on an early ASK Group exit
A31: 30 | B31: ATS | C31: ATS Greens II | D31: Sector 50, Noida | E31: Residential | F31: Completed | N31: Ready to move
A32: 31 | B32: ATS | C32: ATS Pristine Phase 2 | D32: Sector 150, Noida | E32: Residential | F32: Ongoing | J32: 113 | K32: Luxury apartments | O32: Connected to Noida-Greater Noida & Yamuna Expressways
A33: 32 | B33: ATS | C33: ATS Dolce Phase 2 | D33: Sector Zeta-1, Greater Noida West | E33: Residential | F33: Ongoing | O33: New phase recently launched
A34: 33 | B34: ATS | C34: ATS Destinaire | D34: Sector 1, Greater Noida West | E34: Residential | F34: Ongoing | H34: 4.78 (forest area) | K34: 3/4 BHK (HIG) | L34: 1900-2550 sq ft | O34: Miyawaki-technique forest area; low-density living
A35: 34 | B35: ATS | C35: ATS Homekraft Happy Trails | D35: Greater Noida | E35: Residential | F35: Completed | K35: 2/3 BHK | O35: Gated society
A36: 35 | B36: ATS | C36: ATS Dolce | D36: Sector Zeta-1, Greater Noida | E36: Residential | F36: Completed | H36: 14 | K36: 2/3/4 BHK | L36: 1240-2800 sq ft | O36: 7 km from Pari Chowk; near Knowledge Park & Taj Yamuna Expressway
A37: 36 | B37: ATS | C37: ATS Allure | D37: Yamuna Expressway, Greater Noida | E37: Residential | F37: Completed | K37: 2/3 BHK | N37: Completed March 2021 | O37: 88.62K sq m central park | P37: Low-density lifestyle homes
A38: 37 | B38: Experion Group | C38: Experion Elements | D38: Central Noida (Sector 45 area) | E38: Residential | F38: Ongoing | G38: UPRERAPRJ953234 (Ph.II) | O38: Grand Cineplex with large 4K LED screen & Dolby; EV charging per unit | P38: Building plan approved Jan 2024
A39: 38 | B39: Experion Group | C39: Experion Saatori / Sector 151 | D39: Sector 151, Noida | E39: Residential | F39: Upcoming | H39: 5 | K39: 3/4 BHK | N39: Soft launch; RERA registration underway | O39: Clubhouse, pool, gym, sports courts, smart home automation
A40: 39 | B40: Godrej Group | C40: Godrej Golf Links (Exquisite / Windsor / Park Avenue / The Suites / Evoke) | D40: Sector 27, Greater Noida | E40: Residential | F40: Completed | J40: Windsor 114; Park Avenue 1158; The Suites 176 | K40: 2-4 BHK, villas (Evoke) | O40: Township within Godrej Golf Links; 4-6 km from Noida-GN & Yamuna Expressways
...

Sheet Summary
A1: Developer | B1: Total Projects Listed | C1: Completed | D1: Ongoing | E1: Upcoming
A2: Nirala India | B2: =COUNTIF('Developer Projects'!$B$2:$B$86,A2) -> 7 | C2: =COUNTIFS('Developer Projects'!$B$2:$B$86,A2,'Developer Projects'!$F$2:$F$86,"Completed") -> 2 | D2: =COUNTIFS('Developer Projects'!$B$2:$B$86,A2,'Developer Projects'!$F$2:$F$86,"Ongoing") -> 4 | E2: =COUNTIFS('Developer Projects'!$B$2:$B$86,A2,'Developer Projects'!$F$2:$F$86,"Upcoming") -> 1
A3: Nirala World | B3: =COUNTIF('Developer Projects'!$B$2:$B$86,A3) -> 3 | C3: =COUNTIFS('Developer Projects'!$B$2:$B$86,A3,'Developer Projects'!$F$2:$F$86,"Completed") -> 0 | D3: =COUNTIFS('Developer Projects'!$B$2:$B$86,A3,'Developer Projects'!$F$2:$F$86,"Ongoing") -> 2 | E3: =COUNTIFS('Developer Projects'!$B$2:$B$86,A3,'Developer Projects'!$F$2:$F$86,"Upcoming") -> 1
A4: Unibera | B4: =COUNTIF('Developer Projects'!$B$2:$B$86,A4) -> 1 | C4: =COUNTIFS('Developer Projects'!$B$2:$B$86,A4,'Developer Projects'!$F$2:$F$86,"Completed") -> 1 | D4: =COUNTIFS('Developer Projects'!$B$2:$B$86,A4,'Developer Projects'!$F$2:$F$86,"Ongoing") -> 0 | E4: =COUNTIFS('Developer Projects'!$B$2:$B$86,A4,'Developer Projects'!$F$2:$F$86,"Upcoming") -> 0
A5: Bhutani Group | B5: =COUNTIF('Developer Projects'!$B$2:$B$86,A5) -> 6 | C5: =COUNTIFS('Developer Projects'!$B$2:$B$86,A5,'Developer Projects'!$F$2:$F$86,"Completed") -> 5 | D5: =COUNTIFS('Developer Projects'!$B$2:$B$86,A5,'Developer Projects'!$F$2:$F$86,"Ongoing") -> 1 | E5: =COUNTIFS('Developer Projects'!$B$2:$B$86,A5,'Developer Projects'!$F$2:$F$86,"Upcoming") -> 0
A6: Group 108 | B6: =COUNTIF('Developer Projects'!$B$2:$B$86,A6) -> 3 | C6: =COUNTIFS('Developer Projects'!$B$2:$B$86,A6,'Developer Projects'!$F$2:$F$86,"Completed") -> 1 | D6: =COUNTIFS('Developer Projects'!$B$2:$B$86,A6,'Developer Projects'!$F$2:$F$86,"Ongoing") -> 1 | E6: =COUNTIFS('Developer Projects'!$B$2:$B$86,A6,'Developer Projects'!$F$2:$F$86,"Upcoming") -> 1
A7: Gulsan Group | B7: =COUNTIF('Developer Projects'!$B$2:$B$86,A7) -> 8 | C7: =COUNTIFS('Developer Projects'!$B$2:$B$86,A7,'Developer Projects'!$F$2:$F$86,"Completed") -> 5 | D7: =COUNTIFS('Developer Projects'!$B$2:$B$86,A7,'Developer Projects'!$F$2:$F$86,"Ongoing") -> 2 | E7: =COUNTIFS('Developer Projects'!$B$2:$B$86,A7,'Developer Projects'!$F$2:$F$86,"Upcoming") -> 1
A8: ATS | B8: =COUNTIF('Developer Projects'!$B$2:$B$86,A8) -> 8 | C8: =COUNTIFS('Developer Projects'!$B$2:$B$86,A8,'Developer Projects'!$F$2:$F$86,"Completed") -> 5 | D8: =COUNTIFS('Developer Projects'!$B$2:$B$86,A8,'Developer Projects'!$F$2:$F$86,"Ongoing") -> 3 | E8: =COUNTIFS('Developer Projects'!$B$2:$B$86,A8,'Developer Projects'!$F$2:$F$86,"Upcoming") -> 0
A9: Experion Group | B9: =COUNTIF('Developer Projects'!$B$2:$B$86,A9) -> 2 | C9: =COUNTIFS('Developer Projects'!$B$2:$B$86,A9,'Developer Projects'!$F$2:$F$86,"Completed") -> 0 | D9: =COUNTIFS('Developer Projects'!$B$2:$B$86,A9,'Developer Projects'!$F$2:$F$86,"Ongoing") -> 1 | E9: =COUNTIFS('Developer Projects'!$B$2:$B$86,A9,'Developer Projects'!$F$2:$F$86,"Upcoming") -> 1
A10: Godrej Group | B10: =COUNTIF('Developer Projects'!$B$2:$B$86,A10) -> 7 | C10: =COUNTIFS('Developer Projects'!$B$2:$B$86,A10,'Developer Projects'!$F$2:$F$86,"Completed") -> 1 | D10: =COUNTIFS('Developer Projects'!$B$2:$B$86,A10,'Developer Projects'!$F$2:$F$86,"Ongoing") -> 4 | E10: =COUNTIFS('Developer Projects'!$B$2:$B$86,A10,'Developer Projects'!$F$2:$F$86,"Upcoming") -> 2
A11: GYGY Group | B11: =COUNTIF('Developer Projects'!$B$2:$B$86,A11) -> 2 | C11: =COUNTIFS('Developer Projects'!$B$2:$B$86,A11,'Developer Projects'!$F$2:$F$86,"Completed") -> 0 | D11: =COUNTIFS('Developer Projects'!$B$2:$B$86,A11,'Developer Projects'!$F$2:$F$86,"Ongoing") -> 2 | E11: =COUNTIFS('Developer Projects'!$B$2:$B$86,A11,'Developer Projects'!$F$2:$F$86,"Upcoming") -> 0
A12: EON Group | B12: =COUNTIF('Developer Projects'!$B$2:$B$86,A12) -> 1 | C12: =COUNTIFS('Developer Projects'!$B$2:$B$86,A12,'Developer Projects'!$F$2:$F$86,"Completed") -> 0 | D12: =COUNTIFS('Developer Projects'!$B$2:$B$86,A12,'Developer Projects'!$F$2:$F$86,"Ongoing") -> 1 | E12: =COUNTIFS('Developer Projects'!$B$2:$B$86,A12,'Developer Projects'!$F$2:$F$86,"Upcoming") -> 0
A13: CRC Group | B13: =COUNTIF('Developer Projects'!$B$2:$B$86,A13) -> 1 | C13: =COUNTIFS('Developer Projects'!$B$2:$B$86,A13,'Developer Projects'!$F$2:$F$86,"Completed") -> 0 | D13: =COUNTIFS('Developer Projects'!$B$2:$B$86,A13,'Developer Projects'!$F$2:$F$86,"Ongoing") -> 0 | E13: =COUNTIFS('Developer Projects'!$B$2:$B$86,A13,'Developer Projects'!$F$2:$F$86,"Upcoming") -> 1
... A18: Gaursons Group | B18: =COUNTIF('Developer Projects'!$B$2:$B$86,A18) -> 9 | C18: =COUNTIFS('Developer Projects'!$B$2:$B$86,A18,'Developer Projects'!$F$2:$F$86,"Completed") -> 2 | D18: =COUNTIFS('Developer Projects'!$B$2:$B$86,A18,'Developer Projects'!$F$2:$F$86,"Ongoing") -> 7 | E18: =COUNTIFS('Developer Projects'!$B$2:$B$86,A18,'Developer Projects'!$F$2:$F$86,"Upcoming") -> 0

Sheet Notes
A1: Source & methodology
A2: - Compiled from public listings (developer websites, RERA-linked project pages, and portals such as 99acres, Square Yards, WhiteHat Realty, 360PropGuide, CommercialNoida) as of Aug 2026.
A3: - Blank cells mean that detail wasn't stated in the sources found — not that it's zero. Fill in from the developer's brochure/RERA filing where needed.
A4: - 'Status' reflects the most recently stated construction/possession status; large multi-phase projects show the status of their active/latest phase.
A5: - Some rows group several related sub-projects under one entry (e.g. Godrej Golf Links towers, delivered Gaursons legacy portfolio) — split into one row per RERA registration if your site needs that granularity.
A6: - Price ranges, unit counts and areas are as published at time of research and can shift — treat as indicative, not final.
A7: - Images were not included: bulk-downloading/redistributing developer marketing photos raises copyright issues, and this environment has no general internet file-download access. Request an official image pack from each developer's marketing team, or license renders/stock instead.
A8: - Verify RERA numbers, unit counts and possession dates directly on https://www.up-rera.in/projects before publishing on the website.
